Workbook

Sheet 사용법
A1: battery E2E 테스트 시나리오 (최종)
A3: 목적 | B3: 사용자 흐름(로그인 → 수량 입력 → 경로안 비교 → 확정 → 목록·상태 관리 → 기준 정보)을 따라 만든 E2E 시나리오다. 4개 파일을 통합한 e2e-test-scenarios-merged.xlsx에서 중복·가치 없는 시나리오를 정리했다.
A4: 정리 기준 | B4: Day4 '좋은 테스트는 무엇일까' 16쪽: ① 존재 목적이 확실한 테스트만 남긴다 ② 회귀 방지가 잘 되는 것을 남긴다 ③ 핵심 로직을 테스트하는지 본다 ④ 중복 테스트 / 가치 없는 테스트는 삭제한다. 이 기준으로 삭제 21개, 병합 10개를 정리했다. 단 '세 안의 기간·비용 대소 관계'는 PlannerTest와 겹치지만 허주 검증에서 일부 불일치가 확인되어 남겼다.
A5: 삭제·병합 내역 | B5: '삭제·병합 내역' 시트에 처리한 시나리오와 사유를 모두 적었다. 통합본에서 다시 살릴 것이 있으면 이 시트를 보고 가져온다.
A6: ID | B6: 정리하면서 E2E-001부터 새로 매겼다. 통합본 ID는 '통합본 ID' 열에, 4개 원본 파일의 ID는 '출처 ID'(A=E2E_테스트_시나리오.xlsx, B=e2e-test-scenarios.xlsx, C=e2e-test-scenarios03.xlsx(허주), D=e2e_scenarios_v2.xlsx)와 '출처 매핑' 시트에 있다.
A7: 선행 검증 결과 | B7: C(허주)가 2026-10-21에 앱을 별도 인스턴스로 띄워 확인한 판정이다. Pass가 아니면 판정과 케이스 ID를 적었다. 비어 있으면 아직 실제로 확인하지 않은 시나리오다.
A8: 현재 구현 예상 | B8: 일치 예상 = 코드·검증으로 기대와 같다고 본 것. 불일치(알려진 결함) = PRD에 정한 동작과 현재 구현이 다른 것. 일부 불일치 = 일부 입력에서만 다른 것. 확인 필요 = 동작은 확인했지만 PRD 문구와 화면이 다르거나 기대가 분명하지 않은 것.
A9: 남긴 API 시나리오 | B9: API만 호출하는 시나리오(API 401, 음수·0 수량 400, 메모·경로 종류 400, 낡은 마스터 버전 409)는 OrderFlowTests와 일부 겹치지만 판단이 필요해 남겨 두었다. 빼려면 '삭제·병합 내역'에 사유를 적고 삭제한다.
A10: 직접 입력하는 칸 | B10: '시나리오' 시트의 노란색 칸: 실행 결과(미실행·통과·실패·보류), 실행일, 실행자.
A11: 실행 환경 | B11: 앱을 미리 실행해 둔다(기본 http://localhost:8080). 계정 admin / admin. 마스터는 초기값(중국 400/4,000/700, 일본 800/2,000/900, 베트남 200/10,000/550, 인도네시아 300/7,000/450).
A12: 실행 시 주의 | B12: 시나리오는 주문을 만들고 마스터를 바꾼다. 마스터를 바꾼 시나리오는 '정리' 단계에서 반드시 원복해야 다른 시나리오의 기대 값이 맞다.
A13: 범위 밖 (시나리오 없음) | B13: PRD 10장에서 범위 밖으로 확정된 것: 역할별 권한·계정 관리, CSRF 등 보안 요건, 중복 확정 방지, 외부 연동·결제·정산, 경로안 직접 편집. 공장 운영비는 미구현이라 시나리오가 없다.
A14: 확인이 필요한 항목 | B14: ① '가장 빠르게'가 항상 가장 짧은 소요 일수인지(일부 불일치) ② 취소 직후 이동 화면과 존재하지 않는 주문 번호가 HTTP 500인 점 ③ 주문 상세 일별 표에 재고 열이 없는 점 ④ 취소 이력은 화면에서 볼 수 없어 DB 조회가 필요한 점.
A15: 우선순위 | B15: 상: 핵심 흐름·데이터 정합성 / 중: 주요 예외·보조 기능 / 하: 사소한 입력·표시

Sheet 시나리오
A1: ID | B1: 통합본 ID | C1: 흐름 | D1: 시나리오 | E1: 우선순위 | F1: 유형 | G1: PRD 요구사항 | H1: INTENT 원칙 | I1: 사전 조건 | J1: 테스트 단계 | K1: 예상 결과 | L1: 현재 구현 예상 | M1: 선행 검증 결과(허주, 2026-10-21) | N1: 자동화 대상 | O1: 구현된 Playwright | P1: 근거(코드·문서) | Q1: 출처 ID | R1: 실행 결과 | S1: 실행일 | T1: 실행자 | U1: 비고
A2: E2E-001 | B2: E2E-001 | C2: 1. 로그인·접근 통제 | D2: 올바른 계정으로 로그인한다 | E2: 상 | F2: 기능 | G2: R11 | H2: 14 | I2: 로그아웃 상태 | J2: 1. /login 에 접속한다 2. 아이디 admin, 비밀번호 admin 을 입력하고 [로그인]을 누른다 | K2: 주문 목록(/orders)으로 이동한다. 상단 오른쪽에 로그인 아이디 admin 이 보인다. | L2: 일치 예상 | M2: Pass | N2: Y | O2: smoke.spec.ts | P2: AppController.login, OrderFlowTests | Q2: D:E2E-001, A:E2E-001, B:E2E-001, C:HJ-S01-02 | R2: 미실행
A3: E2E-002 | B3: E2E-002 | C3: 1. 로그인·접근 통제 | D3: 틀린 아이디·비밀번호는 이유와 함께 거부된다 | E3: 상 | F3: 견고성 | G3: R11, R9 | H3: 8 | I3: 로그아웃 상태 | J3: 1. 아이디 admin / 비밀번호 wrong 으로 로그인한다 2. 아이디 guest / 비밀번호 admin 으로 로그인한다 | K3: 두 경우 모두 로그인 화면에 머문다. '아이디 또는 비밀번호가 올바르지 않습니다' 가 보인다. 주문 목록으로 넘어가지 않는다. | L3: 일치 예상 | M3: Pass | N3: Y | O3: login-fail.spec.ts (틀린 비밀번호만) | P3: AppController.login, OrderFlowTests.wrongPasswordIsRejected | Q3: D:E2E-002, A:E2E-002, B:E2E-002, C:HJ-S02-01, C:HJ-S02-02 | R3: 미실행
A4: E2E-003 | B4: E2E-003 | C4: 1. 로그인·접근 통제 | D4: 로그인하지 않으면 모든 화면이 막힌다 | E4: 상 | F4: 견고성 | G4: R11 | H4: 14 | I4: 로그아웃 상태 | J4: 1. /orders, /orders/new, /orders/1, /master 에 차례로 직접 접속한다 | K4: 모두 로그인 화면(/login)으로 이동한다. 화면 내용이 잠깐이라도 보이지 않는다. | L4: 일치 예상 | M4: Pass | N4: Y | P4: LoginInterceptor | Q4: D:E2E-003, A:E2E-003, B:E2E-003, C:HJ-S01-01 | R4: 미실행
A5: E2E-004 | B5: E2E-004 | C5: 1. 로그인·접근 통제 | D5: 로그인하지 않으면 API 가 401 을 돌려준다 | E5: 상 | F5: 견고성 | G5: R11 | H5: 14 | I5: 로그아웃 상태 | J5: 1. GET /api/master 를 요청한다 2. POST /api/simulate (본문 {orders:{CHINA:1000}}) 를 요청한다 3. POST /api/orders 를 요청한다 | K5: 세 요청 모두 401 이고, 주문이 생성되지 않는다. | L5: 일치 예상 | M5: Pass | N5: Y | P5: LoginInterceptor, OrderFlowTests.anonymousUserIsSentToLogin | Q5: D:E2E-004, A:E2E-004, C:HJ-S02-03 | R5: 미실행 | U5: page.request 사용
A6: E2E-005 | B6: E2E-006 | C6: 1. 로그인·접근 통제 | D6: 로그아웃하면 다시 로그인해야 한다 | E6: 중 | F6: 기능 | G6: R11 | H6: 14 | I6: 로그인 상태 | J6: 1. [로그아웃]을 누른다 2. /orders 에 접속한다 3. 브라우저 뒤로 가기를 한다 | K6: 1: 로그인 화면으로 이동한다. 2: 다시 로그인 화면으로 이동한다. 3: 로그인 없이 주문 목록 내용이 보이지 않는다. | L6: 일치 예상 | M6: Pass | N6: Y | P6: AppController.logout | Q6: D:E2E-006, B:E2E-004, C:HJ-S01-04 | R6: 미실행
A7: E2E-006 | B7: E2E-009 + E2E-008, E2E-010 | C7: 2. 주문 수량 입력 | D7: 수량 게이지를 조정해도 나라별 합계가 총 수량과 같다 | E7: 중 | F7: 기능 | G7: R1 | I7: 주문 추가 화면, 총 12,000K(각 3,000K) | J7: 1. 총 생산 필요 수를 10,000으로 바꾸고 포커스를 옮긴다 2. 다시 12,000K(각 3,000K)에서 중국을 4,000으로 바꾼다 3. 이어서 인도네시아를 4,000으로 바꾼다 4. 다시 각 3,000K에서 중국을 9,000으로 바꾼다 | K7: 1: 네 나라가 각각 2,500K, 합계 10,000K. 2: 중국 4,000 / 일본 2,000 / 베트남 3,000 / 인도네시아 3,000, 합계 12,000K. 3: 인도네시아 4,000이 되고 맨 왼쪽인 중국이 3,000으로 줄어든다. 합계 12,000K. 4: 중국은 6,000K(중국+일본)까지만 올라가고 일본은 0K가 된다. 합계 12,000K. | L7: 일치 예상 | M7: Pass | N7: Y | P7: order-new.js move() | Q7: D:E2E-009, B:E2E-011, C:HJ-S03-08, C:HJ-S03-09, D:E2E-008, C:HJ-S03-11, D:E2E-010, C:HJ-S03-10 | R7: 미실행
A8: E2E-007 | B8: E2E-011 | C8: 2. 주문 수량 입력 | D8: 총 수량에 1 미만을 넣으면 이전 값으로 돌아간다 | E8: 하 | F8: 견고성 | G8: R1, R9 | H8: 7 | I8: 주문 추가 화면, 총 12,000K | J8: 1. 총 생산 필요 수에 0 을 넣고 포커스를 옮긴다 2. 같은 방법으로 -5 를 넣는다 | K8: 두 경우 모두 입력칸이 12,000 으로 되돌아오고 나라별 수량은 바뀌지 않는다. | L8: 일치 예상 | M8: Pass | N8: Y | P8: order-new.js totalInput change | Q8: D:E2E-011, C:HJ-S04-01 | R8: 미실행
A9: E2E-008 | B9: E2E-012 + E2E-014 | C9: 2. 주문 수량 입력 | D9: 총 수량이 상한을 넘으면 계산하지 않고 이유를 알리고, 경계값은 계산된다 | E9: 상 | F9: 견고성 | G9: R1, R9 | H9: 7, 8 | I9: 주문 추가 화면 | J9: 1. 총 생산 필요 수를 100,001로 바꾸고 [시뮬레이션 실행]을 누른다 2. 100,000으로 바꾸고 [시뮬레이션 실행]을 누른다 3. 1(K)로 바꾸고 [시뮬레이션 실행]을 누른다 | K9: 1: 결과 영역이 나타나지 않고 입력 영역에 '총 생산 필요 수는 100,000K 이하여야 합니다'가 보인다. 2, 3: 오류 없이 경로안 3개가 계산된다. | L9: 일치 예상 | M9: Pass | N9: Y | P9: BatteryService.validateOrders | Q9: D:E2E-012, A:E2E-019, B:E2E-012, C:HJ-S04-02, C:HJ-S04-06, A:E2E-020, C:HJ-S04-05 | R9: 미실행 | U9: 경계값(1K, 100,000K)은 계산되고 100,001K부터 거부된다.
A10: E2E-009 | B10: E2E-013 | C10: 2. 주문 수량 입력 | D10: API 로 음수·0 수량을 보내면 이유와 함께 400 이다 | E10: 중 | F10: 견고성 | G10: R1, R9 | H10: 7, 8 | I10: 로그인 상태 | J10: 1. POST /api/simulate 에 {orders:{CHINA:-1}} 를 보낸다 2. {orders:{CHINA:0,JAPAN:0,VIETNAM:0,INDONESIA:0}} 를 보낸다 | K10: 1: 400, '중국 주문 수량은 0 이상이어야 합니다'. 2: 400, '총 생산 필요 수는 1K 이상이어야 합니다'. 둘 다 계산 결과가 오지 않는다. | L10: 일치 예상 | M10: Pass | N10: Y | P10: BatteryService.validateOrders, OrderFlowTests.emptyOrderIsRejectedWithReason | Q10: D:E2E-013, A:E2E-017, A:E2E-018, C:HJ-S04-03, C:HJ-S04-04 | R10: 미실행 | U10: 화면으로는 만들 수 없는 입력
A11: E2E-010 | B11: E2E-015 | C11: 2. 주문 수량 입력 | D11: 입력을 바꾸면 이전 결과가 사라진다 | E11: 중 | F11: 기능 | G11: R1, R3 | H11: 3 | I11: 시뮬레이션을 실행한 상태 | J11: 1. 나라별 수량 또는 총 수량을 바꾼다 | K11: 결과 영역(옵션·요약·애니메이션·주문 확정)이 숨겨진다. 다시 시뮬레이션해야 확정할 수 있다. | L11: 일치 예상 | M11: Pass | N11: Y | P11: order-new.js invalidate() | Q11: D:E2E-014, A:E2E-021, C:HJ-S03-12 | R11: 미실행 | U11: 낡은 결과로 확정하는 것을 막는 동작
A12: E2E-011 | B12: E2E-016 | C12: 3. 경로안 계산·비교 | D12: 기본 수량으로 시뮬레이션하면 경로안 3개가 나온다 | E12: 상 | F12: 기능 | G12: R2 | H12: 1 | I12: 주문 추가 화면, 기본 수량(각 3,000K) | J12: 1. [시뮬레이션 실행]을 누른다 | K12: '운항비 최소', '가장 빠르게', '가까운 곳부터' 3개 버튼이 보이고 각각 소요 일수·총 비용(억원)·운항비·배 척수가 표시된다. '운항비 최소'가 기본 선택이다. 요약, 배 경로, 일별 생산·비용, 계획에 쓴 마스터 값, 지도 애니메이션이 나온다. | L12: 일치 예상 | M12: Pass | N12: Y | O12: simulation.spec.ts | P12: OrderFlowTests.simulateReturnsThreeOptions, order-new.js | Q12: D:E2E-015, A:E2E-010, B:E2E-009, C:HJ-S03-02, C:HJ-S03-03, C:HJ-S03-05 | R12: 미실행
A13: E2E-012 | B13: E2E-017 | C13: 3. 경로안 계산·비교 | D13: 경로안을 바꾸면 화면의 모든 내용이 그 안으로 바뀐다 | E13: 중 | F13: 기능 | G13: R2 | H13: 1 | I13: 시뮬레이션 결과가 보이는 상태 | J13: 1. '가장 빠르게'를 누른다 2. '가까운 곳부터'를 누른다 | K13: 눌린 버튼이 선택 표시가 되고, 요약 제목의 안 이름·소요 일수·비용·배 경로 표가 선택한 안의 값으로 바뀐다. 세 안의 값은 서로 달라도 되지만 한 화면 안에서 요약과 표는 항상 같은 안을 가리킨다. | L13: 일치 예상 | M13: Pass | N13: Y | O13: simulation.spec.ts | P13: order-new.js renderResult | Q13: D:E2E-016, A:E2E-011, B:E2E-010, C:HJ-S03-04 | R13: 미실행
A14: E2E-013 | B14: E2E-018 | C14: 3. 경로안 계산·비교 | D14: 세 안의 기간·비용 대소 관계가 맞는다 | E14: 상 | F14: 기능 | G14: R2 | H14: 1, 10 | I14: 기본 수량으로 시뮬레이션 | J14: 1. 세 안의 소요 일수, 운항비, 생산 원가를 읽는다 | K14: '가장 빠르게'의 소요 일수가 세 안 중 가장 짧고, '운항비 최소'의 운항비가 세 안 중 가장 낮다. 생산 원가는 세 안이 같다. | L14: 일치 예상 | M14: 불일치 (HJ-S14-08) | N14: Y | O14: simulation.spec.ts (E2E-013) | P14: PlannerTest.costOptionIsNotMoreExpensiveAndFastOptionIsNotSlower | Q14: D:E2E-017, A:E2E-012, C:HJ-S14-07, C:HJ-S14-08 | R14: 미실행 | U14: 기본 수량에서는 소요 일수가 운항비 최소 26일 / 가장 빠르게 20일 / 가까운 곳부터 21일이라 기대와 맞는다. 단 배 1척으로 설정한 28개 조합 중 2개(5000/2000/0/8000 → 가장 빠르게 47일 vs 가까운 곳부터 45일, 4001/2001/10001/7001 → 77일 vs 76일)에서 '가까운 곳부터'가 더 빨랐다. 원본 v2의 '운항비 최소 ≤ 가까운 곳부터'(소요 일수) 기대는 기본값 결과(26일 vs 21일)와 맞지 않아 뺐다. [분리] 이 시나리오는 기본 수량 기준이다. 불일치 조합(배 1척, 5000/2000/0/8000)은 E2E-013b로 분리했다. 두 번째 조합(4001/2001/10001/7001, 77일 vs 76일)은 아직 자동화하지 않았다.
A15: E2E-013b | B15: - | C15: 3. 경로안 계산·비교 | D15: 배 1척일 때도 가장 빠르게의 소요 일수가 가장 짧다 | E15: 중 | F15: 기능 | G15: R2 | H15: 1 | I15: 마스터에서 배 척수를 1로 저장해 둠 (끝나면 3으로 원복) | J15: 1. 마스터에서 배 척수를 1로 저장한다 2. 중국 5,000 / 일본 2,000 / 베트남 0 / 인도네시아 8,000으로 시뮬레이션한다 3. 세 안의 소요 일수를 읽는다 4. 정리: 배 척수를 3으로 되돌린다 | K15: '가장 빠르게'의 소요 일수가 세 안 중 가장 짧다. | L15: 불일치(알려진 결함) | M15: 불일치 (HJ-S14-08) | N15: Y | O15: simulation.spec.ts (E2E-013b, test.fail) | P15: PRD 6장 경로안의 정의(가장 빠르게 = 총 소요 일수가 가장 짧은 안), HJ-S14-08 | Q15: E2E-013에서 분리 (C:HJ-S14-08) | R15: 미실행 | U15: E2E-013은 기본 수량에서 통과하므로 불일치 조합만 따로 뗐다. 이 입력에서 가장 빠르게 47일, 가까운 곳부터 45일로 기대와 다르다(직접 재현). 고치기 전에는 Playwright test.fail()로 표시하고, 고치면 표시를 지운다. 마스터를 바꾸므로 원복 필수.
A16: E2E-014 | B16: E2E-028 | C16: 3. 경로안 계산·비교 | D16: 총량이 같아도 나라별 배분을 바꾸면 결과가 달라진다 | E16: 중 | F16: 기능 | G16: R1, R2 | I16: 로그인 상태 | J16: 1. 총량은 같게 두고 나라별 배분을 바꿔 가며 시뮬레이션을 반복한다 | K16: 배분마다 소요 일수·비용이 각각 계산되어 표시된다. (배분은 사용자가 정한다) | L16: 일치 예상 | N16: Y | P16: PRD 2장 목표 6 | Q16: A:E2E-022 | R16: 미실행
A17: E2E-015 | B17: E2E-031 + E2E-032 | C17: 4. 주문 확정 | D17: 확정하면 상세로 이동하고 메모가 반영된다 | E17: 상 | F17: 기능 | G17: R3, R7 | H17: 2, 9 | I17: 시뮬레이션 결과가 보이는 상태('운항비 최소') | J17: 1. 메모를 비운 채 [주문 확정]을 누른다 2. 새 시뮬레이션 후 메모에 '긴급 주문'을 적고 [주문 확정]을 누른다 | K17: 1: 주문 상세(/orders/{번호})로 이동한다. 상태 '확정', 경로 '운항비 최소', 메모 '-', 작성자 admin. 상태 이력에 1행(이전 '-', 새 '확정', 변경한 사람 admin)이 있다. 2: 상세의 메모 칸에 '긴급 주문'이 보인다. | L17: 일치 예상 | M17: Pass | N17: Y | P17: BatteryService.confirm, OrderFlowTests.confirmThenDetailAndStatusFlow | Q17: D:E2E-025, A:E2E-030, A:E2E-032, A:E2E-033, B:E2E-014, C:HJ-S05-01, C:HJ-S05-02, C:HJ-S05-03, D:E2E-026, B:E2E-015 | R17: 미실행 | U17: 주문이 2건 생긴다
A18: E2E-016 | B18: E2E-033 + E2E-034 | C18: 4. 주문 확정 | D18: 확정한 주문은 선택한 안과 화면에서 본 계산 그대로 저장된다 | E18: 상 | F18: 기능 | G18: R3 | H18: 2 | I18: 시뮬레이션 결과가 보이는 상태('가장 빠르게' 선택) | J18: 1. '가장 빠르게'를 선택하고 화면의 소요 일수·생산 원가·운항비·총 비용·배 경로 표를 기록한다 2. [주문 확정]을 누른다 3. 상세의 같은 항목을 비교한다 4. 주문 목록의 같은 주문 행(경로·소요 일수·총 비용)과 비교한다 5. 다른 시뮬레이션에서 '가까운 곳부터'를 선택해 확정하고 상세의 경로를 확인한다 | K18: 상세의 요약·배 경로·나라별 수량·방문 횟수가 시뮬레이션 때와 완전히 같다. 목록의 경로 '가장 빠르게', 소요 일수, 총 비용도 같다. 5: 상세의 경로가 '가까운 곳부터'이고 값이 선택한 안과 같다. | L18: 일치 예상 | N18: Y | P18: BatteryService.confirm(서버 재계산), PRD R3 | Q18: D:E2E-027, A:E2E-031, D:E2E-028 | R18: 미실행 | U18: 주문이 2건 생긴다
A19: E2E-017 | B19: E2E-036 | C19: 4. 주문 확정 | D19: API 로 1,001자 메모·없는 경로 종류를 보내면 이유와 함께 400 이다 | E19: 중 | F19: 견고성 | G19: R3, R9 | H19: 7, 8 | I19: 로그인 상태, 현재 마스터 버전을 /api/master 로 조회 | J19: 1. POST /api/orders 에 메모 1,001자를 보낸다 2. routeType 을 'XXX' 로 보낸다 | K19: 1: 400, '메모는 1000자 이하로 입력하세요'. 2: 400, '선택한 경로를 찾을 수 없습니다'. 두 경우 모두 주문이 생기지 않는다. | L19: 일치 예상 | N19: Y | P19: BatteryService.confirm | Q19: D:E2E-030 | R19: 미실행 | U19: 화면으로는 만들 수 없는 입력
A20: E2E-018 | B20: E2E-037 | C20: 4. 주문 확정 | D20: 시뮬레이션 뒤 기준 정보가 바뀌면 확정이 거부된다 | E20: 상 | F20: 견고성 | G20: R5, R9 | H20: 2, 3, 8 | I20: 탭(브라우저 컨텍스트) 2개, 마스터 초기값 | J20: 1. 탭 A: 시뮬레이션을 실행한다(확정하지 않는다) 2. 탭 B: 마스터에서 배 척수를 3 → 2 로 바꿔 저장한다 3. 탭 A: [주문 확정]을 누른다 4. 탭 A: 다시 시뮬레이션을 실행하고 [주문 확정]을 누른다 5. 정리: 배 척수를 3 으로 되돌린다 | K20: 3: 주문이 만들어지지 않고 '시뮬레이션 이후 마스터 데이터가 바뀌었습니다. 다시 시뮬레이션해 주세요' 가 보인다. 4: 새 기준으로 확정되어 상세로 이동한다. | L20: 일치 예상 | M20: Pass | N20: Y | P20: BatteryService.confirm, OrderFlowTests.confirmFailsWhenMasterChangedAfterSimulation | Q20: D:E2E-031, A:E2E-050, A:E2E-051, B:E2E-017, C:HJ-S06-01, C:HJ-S06-02 | R20: 미실행 | U20: 원복 필수
A21: E2E-019 | B21: E2E-038 | C21: 4. 주문 확정 | D21: API 로 낡은 마스터 버전을 보내면 409 로 거부된다 | E21: 중 | F21: 견고성 | G21: R5 | H21: 3, 8 | I21: 로그인 상태 | J21: 1. POST /api/orders 에 masterVersion 을 현재보다 작은 값(0)으로 보낸다 | K21: 409 이고 conflict 가 true, '시뮬레이션 이후 마스터 데이터가 바뀌었습니다…' 메시지가 온다. 주문이 생기지 않는다. | L21: 일치 예상 | N21: Y | P21: BatteryService.confirm, AppController.apiError | Q21: D:E2E-032 | R21: 미실행
A22: E2E-020 | B22: E2E-039 | C22: 4. 주문 확정 | D22: 시뮬레이션만으로는 주문이 생기지 않는다 | E22: 중 | F22: 기능 | G22: R3 | I22: 주문 목록의 '전체' 건수를 기록해 둠 | J22: 1. 시뮬레이션을 실행한다 2. 확정하지 않고 주문 목록으로 이동한다 3. (참고) 마스터 변경으로 확정이 거부된 경우에도 건수를 확인한다 | K22: 주문 건수가 그대로다. 거부된 확정도 주문을 만들지 않는다. | L22: 일치 예상 | N22: Y | P22: PRD R3 | Q22: B:E2E-013 | R22: 미실행
A23: E2E-021 | B23: E2E-040 | C23: 4. 주문 확정 | D23: 확정 요청에 끼워 넣은 계산값은 무시되고 서버가 다시 계산한다 | E23: 상 | F23: 견고성 | G23: R3 | H23: 2 | I23: 로그인 상태 | J23: 1. POST /api/orders에 수량 3,000K×4, 경로안 COST와 함께 totalCost=1, totalDays=1 같은 추가 필드를 보낸다 2. 만들어진 주문을 목록·상세에서 확인한다 | K23: 추가 필드는 무시되고 서버가 다시 계산한 값(소요 26일 등)으로 저장된다. | L23: 일치 예상 | M23: Pass | N23: Y | P23: BatteryService.confirm(서버 재계산) | Q23: A:E2E-035, C:HJ-S05-07 | R23: 미실행 | U23: page.request 사용
A24: E2E-022 | B24: E2E-042 + E2E-072 | C24: 4. 주문 확정 | D24: 마스터를 바꿔도 확정한 주문은 그대로고, 새 주문만 새 기준을 따른다 | E24: 상 | F24: 기능 | G24: R4, R5, R8 | H24: 4 | I24: 확정한 주문이 1건, 마스터 초기값 | J24: 1. 주문 상세의 소요 일수·비용·배 경로, '계획에 쓴 마스터 값'(배 척수, 공장 값, 항로)을 기록한다 2. 마스터에서 중국 하루 최대 생산량 400 → 100, 배 척수 3 → 1로 저장한다 3. 같은 주문 상세와 주문 목록의 같은 행을 다시 확인한다 4. 같은 수량으로 새로 시뮬레이션하고 확정한 뒤 새 주문 상세를 연다 5. 정리: 마스터를 원복한다 | K24: 3: 상세와 목록의 모든 값이 1에서 기록한 값과 같다. '계획에 쓴 마스터 값'에는 변경 전 값(중국 400, 배 3척)이 그대로 보인다. 4: 새 주문은 새 기준 값으로, 과거 주문은 확정 당시 값 그대로 표시된다. | L24: 일치 예상 | M24: Pass | N24: Y | P24: StoredPlan, OrderFlowTests.masterUpdateBumpsVersionAndKeepsConfirmedPlans | Q24: D:E2E-033, A:E2E-052, C:HJ-S11-06, A:E2E-053, A:E2E-101 | R24: 미실행 | U24: 원복 필수. 새 주문이 1건 생긴다
A25: E2E-023 | B25: E2E-043 | C25: 5. 주문 목록·상세 | D25: 목록에 필요한 정보가 최신순으로 나온다 | E25: 중 | F25: 기능 | G25: R6 | I25: 확정한 주문이 2건 이상 | J25: 1. [주문 목록]을 누른다 | K25: 열: 주문번호, 확정 일시, 총 수량(K), 경로, 소요 일수, 총 비용(억원), 상태, 작성자. 방금 확정한 주문이 가장 위에 있고 번호가 내림차순이다. | L25: 일치 예상 | M25: Pass | N25: Y | P25: orders.html, findAllByOrderByIdDesc | Q25: D:E2E-034, A:E2E-060, A:E2E-034, B:E2E-006, C:HJ-S05-06 | R25: 미실행
A26: E2E-024 | B26: E2E-044 | C26: 5. 주문 목록·상세 | D26: 상태 필터와 건수가 맞다 | E26: 중 | F26: 기능 | G26: R6 | H26: 9 | I26: 확정·진행·완료 주문이 각각 1건 이상 | J26: 1. '전체', '확정', '진행', '완료', '취소' 칩의 건수를 읽는다 2. '진행' 칩을 누른다 | K26: 1: 전체 = 확정+진행+완료+취소 이고 각 건수가 실제 행 수와 같다. 2: 진행 주문만 보이고 '진행' 칩이 활성 표시다. | L26: 확인 필요 | M26: Pass | N26: Y | P26: BatteryService.countByStatus | Q26: D:E2E-035, A:E2E-061, B:E2E-007, C:HJ-S10-01, C:HJ-S10-02, C:HJ-S10-03, C:HJ-S10-04 | R26: 미실행 | U26: '취소' 건수는 취소 주문이 삭제돼 늘지 않는다(PRD 7장). 개발 DB 에 옛 취소 건이 남아 있을 수 있음
A27: E2E-025 | B27: E2E-046 | C27: 5. 주문 목록·상세 | D27: 상세에 확정 당시 내용과 이력이 모두 보인다 | E27: 상 | F27: 기능 | G27: R6, R4 | H27: 4, 9 | I27: 확정한 주문이 1건 | J27: 1. 주문 상세를 연다 | K27: 확정 일시, 작성자, 경로, 메모, 상태 이력, 요약, 나라별 주문 수량·방문 횟수, 배 경로, 일별 생산·비용(펼치기), 계획에 쓴 마스터 값(펼치기), 지도 애니메이션이 모두 있다. 지도 애니메이션은 자동 재생되지 않는다. | L27: 일치 예상 | M27: Pass | N27: Y | P27: order-detail.html, planview.js | Q27: D:E2E-037, A:E2E-062, C:HJ-S05-04 | R27: 미실행
A28: E2E-026 | B28: E2E-048 | C28: 5. 주문 목록·상세 | D28: 주문 상세에서 일별 재고를 지도 애니메이션으로 볼 수 있다 | E28: 중 | F28: 기능 | G28: R6 | I28: 확정한 주문이 1건 | J28: 1. 확정한 주문의 상세를 연다 2. 지도 애니메이션 슬라이더를 0일, 1일, 3일, 11일로 옮기며 나라별 재고 숫자를 읽는다 | K28: 일별 재고가 나라별로 보인다. 0일은 모든 나라가 0, 1일은 하루 최대 생산량만큼(중국 400·일본 800·베트남 200·인도네시아 300), 3일에는 일본이 0(그날 수거), 11일에는 중국이 0(그날 수거)이다. 수거한 날 그 나라 재고는 0으로 돌아간다. 일별 생산·비용 표에는 재고 열이 없다. 재고는 지도 애니메이션에서 본다. | L28: 일치 예상 | M28: Pass | N28: Y | O28: e2e-026.spec.ts (e2e/huju) | P28: PRD R6(문구 보정 필요), planview.js, anim.js(stockAt) | Q28: C:HJ-S05-08 | R28: 미실행 | U28: A안으로 변경(2026-10-21). 원래는 일별 표에서 생산·재고를 보는 시나리오였으나 표에는 재고 열이 없고 재고는 지도 애니메이션 슬라이더로 일별 확인된다. 수치는 기본 마스터와 '운항비 최소' 경로안 기준이다. PRD R6 문구를 '일별 생산·재고(재고는 지도 애니메이션)'로 보정할지는 팀 확인이 필요하다.
A29: E2E-027 | B29: E2E-050 | C29: 6. 주문 상태 관리 | D29: 확정 → 진행으로 바꾸고 이력이 남는다 | E29: 상 | F29: 기능 | G29: R7 | H29: 9 | I29: 상태 '확정' 주문의 상세 | J29: 1. [진행(으)로 변경]을 누른다 2. 확인 창의 문구를 확인하고 [확인]을 누른다 | K29: 1: '진행(으)로 바꿉니다. 계속할까요?' 확인 창이 뜬다. 2: '상태를 '진행'(으)로 바꿨습니다' 가 보이고 상태 배지가 '진행'이다. 이력에 '확정 → 진행, 변경한 사람 admin' 행이 추가된다. | L29: 일치 예상 | M29: Pass | N29: Y | P29: BatteryService.changeStatus | Q29: D:E2E-039, A:E2E-070, A:E2E-080, B:E2E-018, C:HJ-S07-01, C:HJ-S07-03 | R29: 미실행 | U29: page.on('dialog') 로 확인 창 처리
A30: E2E-028 | B30: E2E-051 | C30: 6. 주문 상태 관리 | D30: 확인 창에서 취소하면 상태가 바뀌지 않는다 | E30: 중 | F30: 견고성 | G30: R7 | H30: 9 | I30: 상태 '확정' 주문의 상세 | J30: 1. [진행(으)로 변경]을 누른다 2. 확인 창에서 [취소]를 누른다 | K30: 상태는 '확정'이고 이력 행 수도 그대로다. | L30: 일치 예상 | M30: Pass | N30: Y | P30: order-detail.html | Q30: D:E2E-040, C:HJ-S07-02 | R30: 미실행
A31: E2E-029 | B31: E2E-052 | C31: 6. 주문 상태 관리 | D31: 진행 → 완료로 바꾸면 더 바꿀 수 없다 | E31: 상 | F31: 기능 | G31: R7 | H31: 9 | I31: 상태 '진행' 주문의 상세 | J31: 1. [완료(으)로 변경]을 누르고 확인한다 | K31: 상태 '완료'. 변경 버튼이 사라지고 '최종 상태라 더 바꿀 수 없습니다.' 가 보인다. 이력이 '확정 → 진행 → 완료' 순서로 3행이다(첫 행의 이전 상태는 '-'). | L31: 일치 예상 | M31: Pass | N31: Y | P31: OrderStatus.next, OrderFlowTests.confirmThenDetailAndStatusFlow | Q31: D:E2E-041, A:E2E-071, B:E2E-019, C:HJ-S07-04 | R31: 미실행
A32: E2E-030 | B32: E2E-053 | C32: 6. 주문 상태 관리 | D32: 화면에는 허용된 다음 상태 버튼만 있다 | E32: 중 | F32: 기능 | G32: R7 | H32: 9 | I32: 상태 '확정', '진행' 주문 각 1건 | J32: 1. '확정' 주문 상세의 변경 버튼을 본다 2. '진행' 주문 상세의 변경 버튼을 본다 | K32: 1: '진행(으)로 변경', '취소(으)로 변경' 만 있다. 2: '완료(으)로 변경', '취소(으)로 변경' 만 있다. | L32: 일치 예상 | M32: Pass | N32: Y | P32: OrderStatus.next | Q32: D:E2E-042, B:E2E-022, C:HJ-S05-05 | R32: 미실행
A33: E2E-031 | B33: E2E-054 | C33: 6. 주문 상태 관리 | D33: 허용되지 않은 상태 변경은 직접 요청해도 거부된다 | E33: 상 | F33: 견고성 | G33: R7 | H33: 9, 8 | I33: 상태 '확정' 주문, 상세의 version 값 확인, 완료 주문 1건 | J33: 1. 로그인한 세션으로 POST /orders/{확정 주문}/status 에 status=COMPLETED, version=현재값을 보낸다 2. 완료 주문에 status=CANCELED, version=현재값을 보낸다 | K33: 1: 상태는 '확정' 그대로이고 '확정 상태에서는 완료(으)로 바꿀 수 없습니다' 가 상세에 보인다. 2: 상태는 '완료' 그대로이고 '완료 상태에서는 취소(으)로 바꿀 수 없습니다' 가 보인다. 이력 행이 늘지 않는다. | L33: 일치 예상 | M33: Pass | N33: Y | P33: BatteryService.changeStatus, OrderFlowTests | Q33: D:E2E-043, A:E2E-072, A:E2E-073, A:E2E-074, A:E2E-079, C:HJ-S08-01 | R33: 미실행 | U33: 버튼이 없는 요청이라 page.request 사용
A34: E2E-032 | B34: E2E-055 + E2E-057, E2E-060 | C34: 6. 주문 상태 관리 | D34: 확정·진행 주문을 취소하면 목록에서 사라지고 이력은 남는다 | E34: 상 | F34: 기능 | G34: R7 | H34: 9 | I34: 상태 '확정' 주문 | J34: 1. 상태 '확정' 주문 상세에서 [취소(으)로 변경]을 누르고 확인한다 2. 주문 목록을 직접 연다 3. 같은 주문 번호로 DB(order_status_history)를 조회한다 4. '취소' 칩의 건수를 보고 '취소' 필터를 누른다 5. 상태 '진행' 주문으로도 1~2를 반복한다 | K34: 2: 해당 주문이 목록에 없고 '전체' 건수가 1 줄었다. 3: 그 주문 번호의 이력이 남아 있고 마지막 행이 '취소'이다. (이력은 주문 번호만 가진 별도 테이블) 4: 취소로 '취소' 건수가 늘지 않고, 필터에는 방금 취소한 주문이 없어 '주문이 없습니다.'가 보인다. (취소=삭제) 5: 진행 주문도 같은 결과다. | L34: 일치 예상 | M34: Pass | N34: N | P34: BatteryService.changeStatus, PRD 7장, INTENT 5.6 | Q34: D:E2E-044, A:E2E-075, A:E2E-078, B:E2E-020, C:HJ-S09-01, C:HJ-S09-04, D:E2E-046, A:E2E-076, B:E2E-021, C:HJ-S09-03 | R34: 미실행 | U34: 이력은 화면에서 볼 수 없어 DB 조회가 필요하다. 개발 DB에는 삭제 로직 이전에 취소된 주문이 남아 있어 '취소 1'로 보일 수 있으니 새 DB 기준으로 확인한다. 취소 직후 이동 화면은 취소 직후 시나리오(별도)에서 본다.
A35: E2E-033 | B35: E2E-056 | C35: 6. 주문 상태 관리 | D35: 취소 직후에는 이전 페이지로 이동한다 | E35: 상 | F35: 기능 | G35: R7 | H35: 8 | I35: 상태 '확정' 주문의 상세(목록에서 들어옴) | J35: 1. [취소(으)로 변경]을 누르고 확인한다 | K35: 정한 동작: 이전 페이지(주문 목록)로 이동하고 오류 화면이 열리지 않는다. 현재 구현: 삭제된 주문의 상세(/orders/{번호})로 이동해 HTTP 500 기본 오류 화면(Whitelabel Error Page)이 열린다. | L35: 불일치(알려진 결함) | M35: 불일치 (HJ-S09-02) | N35: Y | P35: PRD 7장, INTENT 5.6·9장 1번 | Q35: D:E2E-045, A:E2E-077, C:HJ-S09-02 | R35: 미실행 | U35: 고치기 전에는 Playwright test.fail() 로 표시. 고친 뒤 일반 테스트로 전환
A36: E2E-034 | B36: E2E-058 + E2E-061 | C36: 6. 주문 상태 관리 | D36: 두 사람이 같은 주문을 동시에 바꾸면 먼저 한 쪽만 인정된다 | E36: 상 | F36: 견고성 | G36: R10 | H36: 5, 8 | I36: 브라우저 컨텍스트 2개, 상태 '확정' 주문 | J36: 1. 탭 A, 탭 B 에서 같은 주문 상세를 연다 2. 탭 A: [진행(으)로 변경]을 누르고 확인한다 3. 탭 B(새로 고침하지 않음): [취소(으)로 변경]을 누르고 확인한다 | K36: 3: 상태는 '진행' 그대로이고 주문이 삭제되지 않는다. '다른 사용자가 먼저 이 주문을 변경했습니다. 화면을 새로 고쳐 현재 상태를 확인한 뒤 다시 시도해 주세요' 가 보인다. 이력에는 탭 A 의 변경만 있다. | L36: 일치 예상 | M36: Pass | N36: Y | P36: BatteryService.changeStatus, OrderFlowTests | Q36: D:E2E-047, A:E2E-090, A:E2E-091, B:E2E-023, C:HJ-S08-02, A:E2E-092 | R36: 미실행 | U36: 같은 시점에 들어온 두 요청을 API로 보내 한쪽만 성공하는지 보는 변형은 이 시나리오와 같은 규칙이라 합쳤다(낙관적 락, version).
A37: E2E-035 | B37: E2E-059 | C37: 6. 주문 상태 관리 | D37: 없는 주문 번호로 접속하면 이유를 알려 준다 | E37: 중 | F37: 견고성 | G37: R9 | H37: 8 | I37: 로그인 상태 | J37: 1. /orders/999999 에 접속한다 | K37: 정한 동작: '주문을 찾을 수 없습니다' 같은 안내가 보인다. 현재 구현: 안내 없이 HTTP 500 기본 오류 화면이 열린다. | L37: 불일치(알려진 결함) | M37: 불일치 (HJ-S13-01) | N37: Y | P37: INTENT 9장 2번, BatteryService.getOrder | Q37: D:E2E-048, A:E2E-064, B:E2E-028, C:HJ-S13-01 | R37: 미실행 | U37: 고치기 전에는 test.fail()
A38: E2E-036 | B38: E2E-062 | C38: 7. 기준 정보(마스터) 관리 | D38: 마스터 화면에 현재 값이 보인다 | E38: 중 | F38: 기능 | G38: R8 | H38: 13 | I38: 로그인 상태, 마스터 초기값 | J38: 1. 상단 [마스터 데이터]를 누른다 | K38: 공장 표(중국 400/4,000/700, 일본 800/2,000/900, 베트남 200/10,000/550, 인도네시아 300/7,000/450), 배 척수 3, 척당 일 운항비 1, 항로 표(항해 일수)가 보인다. '값을 바꿔도 이미 확정한 주문의 계획은 바뀌지 않습니다' 안내가 있다. | L38: 일치 예상 | M38: Pass | N38: Y | P38: master.html, BatteryService.initDefaults | Q38: D:E2E-049, A:E2E-040, A:E2E-047, B:E2E-024, C:HJ-S11-01 | R38: 미실행 | U38: 초기값이 아닌 DB 에서는 기대 값이 다를 수 있음
A39: E2E-037 | B39: E2E-063 | C39: 7. 기준 정보(마스터) 관리 | D39: 값을 바꿔 저장하면 유지되고 버전이 오른다 | E39: 상 | F39: 기능 | G39: R8 | H39: 13, 3 | I39: 마스터 화면 | J39: 1. GET /api/master 로 version 을 기록한다 2. 중국 하루 최대 생산량을 400 → 500 으로 바꿔 [저장]한다 3. 화면을 새로 고치고 GET /api/master 를 다시 조회한다 4. 정리: 400 으로 되돌려 저장한다 | K39: 2: '마스터 데이터를 저장했습니다' 가 보인다. 3: 중국 하루 최대가 500 으로 남아 있고 version 이 1 올라 있다. | L39: 일치 예상 | M39: Pass | N39: Y | P39: BatteryService.updateMaster, OrderFlowTests.masterUpdateBumpsVersionAndKeepsConfirmedPlans | Q39: D:E2E-050, A:E2E-041, B:E2E-025, C:HJ-S11-04, C:HJ-S11-08 | R39: 미실행 | U39: 원복 필수
A40: E2E-038 | B40: E2E-064 | C40: 7. 기준 정보(마스터) 관리 | D40: 바뀐 마스터 값이 새 시뮬레이션에 반영된다 | E40: 중 | F40: 기능 | G40: R8 | H40: 13 | I40: 마스터 화면 | J40: 1. 기본 수량으로 시뮬레이션해 '운항비 최소'의 소요 일수를 기록한다 2. 마스터에서 중국 하루 최대 생산량을 400 → 100 으로 저장한다 3. 같은 수량으로 시뮬레이션한다 4. 정리: 400 으로 원복한다 | K40: 3: 소요 일수가 늘어나거나 같고, '계획에 쓴 마스터 값'의 중국 하루 최대가 100 으로 표시된다. 코드 수정 없이 값만으로 결과가 바뀐다. | L40: 일치 예상 | M40: Pass | N40: Y | P40: PRD R8 | Q40: D:E2E-051, A:E2E-042, B:E2E-027, C:HJ-S11-02, C:HJ-S11-03, C:HJ-S11-05, C:HJ-S11-07 | R40: 미실행 | U40: 원복 필수
...

Sheet 요약
A1: E2E 시나리오 최종 현황
A3: 정리 전·후
A4: 구분 | B4: 시나리오 수
A5: 통합본 | B5: 72
A6: 삭제 (사유 있음) | B6: =COUNTIF('삭제·병합 내역'!$C$2:$C$32,"삭제")
A7: 병합 (다른 시나리오에 흡수) | B7: =COUNTIF('삭제·병합 내역'!$C$2:$C$32,"병합")
A8: 최종 시나리오 | B8: =COUNTA(시나리오!$A$2:$A$47)
A9: 검산 (통합본 − 삭제 − 병합) | B9: =B5-B6-B7
A11: 흐름별
A12: 흐름 | B12: 시나리오 수 | C12: 상 | D12: 중 | E12: 하
A13: 1. 로그인·접근 통제 | B13: =COUNTIF(시나리오!$C$2:$C$47,A13) | C13: =COUNTIFS(시나리오!$C$2:$C$47,$A13,시나리오!$E$2:$E$47,"상") | D13: =COUNTIFS(시나리오!$C$2:$C$47,$A13,시나리오!$E$2:$E$47,"중") | E13: =COUNTIFS(시나리오!$C$2:$C$47,$A13,시나리오!$E$2:$E$47,"하")
A14: 2. 주문 수량 입력 | B14: =COUNTIF(시나리오!$C$2:$C$47,A14) | C14: =COUNTIFS(시나리오!$C$2:$C$47,$A14,시나리오!$E$2:$E$47,"상") | D14: =COUNTIFS(시나리오!$C$2:$C$47,$A14,시나리오!$E$2:$E$47,"중") | E14: =COUNTIFS(시나리오!$C$2:$C$47,$A14,시나리오!$E$2:$E$47,"하")
A15: 3. 경로안 계산·비교 | B15: =COUNTIF(시나리오!$C$2:$C$47,A15) | C15: =COUNTIFS(시나리오!$C$2:$C$47,$A15,시나리오!$E$2:$E$47,"상") | D15: =COUNTIFS(시나리오!$C$2:$C$47,$A15,시나리오!$E$2:$E$47,"중") | E15: =COUNTIFS(시나리오!$C$2:$C$47,$A15,시나리오!$E$2:$E$47,"하")
A16: 4. 주문 확정 | B16: =COUNTIF(시나리오!$C$2:$C$47,A16) | C16: =COUNTIFS(시나리오!$C$2:$C$47,$A16,시나리오!$E$2:$E$47,"상") | D16: =COUNTIFS(시나리오!$C$2:$C$47,$A16,시나리오!$E$2:$E$47,"중") | E16: =COUNTIFS(시나리오!$C$2:$C$47,$A16,시나리오!$E$2:$E$47,"하")
A17: 5. 주문 목록·상세 | B17: =COUNTIF(시나리오!$C$2:$C$47,A17) | C17: =COUNTIFS(시나리오!$C$2:$C$47,$A17,시나리오!$E$2:$E$47,"상") | D17: =COUNTIFS(시나리오!$C$2:$C$47,$A17,시나리오!$E$2:$E$47,"중") | E17: =COUNTIFS(시나리오!$C$2:$C$47,$A17,시나리오!$E$2:$E$47,"하")
A18: 6. 주문 상태 관리 | B18: =COUNTIF(시나리오!$C$2:$C$47,A18) | C18: =COUNTIFS(시나리오!$C$2:$C$47,$A18,시나리오!$E$2:$E$47,"상") | D18: =COUNTIFS(시나리오!$C$2:$C$47,$A18,시나리오!$E$2:$E$47,"중") | E18: =COUNTIFS(시나리오!$C$2:$C$47,$A18,시나리오!$E$2:$E$47,"하")
A19: 7. 기준 정보(마스터) 관리 | B19: =COUNTIF(시나리오!$C$2:$C$47,A19) | C19: =COUNTIFS(시나리오!$C$2:$C$47,$A19,시나리오!$E$2:$E$47,"상") | D19: =COUNTIFS(시나리오!$C$2:$C$47,$A19,시나리오!$E$2:$E$47,"중") | E19: =COUNTIFS(시나리오!$C$2:$C$47,$A19,시나리오!$E$2:$E$47,"하")
A20: 8. 대표 종단 흐름 | B20: =COUNTIF(시나리오!$C$2:$C$47,A20) | C20: =COUNTIFS(시나리오!$C$2:$C$47,$A20,시나리오!$E$2:$E$47,"상") | D20: =COUNTIFS(시나리오!$C$2:$C$47,$A20,시나리오!$E$2:$E$47,"중") | E20: =COUNTIFS(시나리오!$C$2:$C$47,$A20,시나리오!$E$2:$E$47,"하")
A21: 합계 | B21: =SUM(B13:B20) | C21: =SUM(C13:C20) | D21: =SUM(D13:D20) | E21: =SUM(E13:E20)
A23: 현재 구현 예상
A24: 구분 | B24: 시나리오 수
A25: 일치 예상 | B25: =COUNTIF(시나리오!$L$2:$L$47,A25)
A26: 불일치* | B26: =COUNTIF(시나리오!$L$2:$L$47,A26)
A27: 일부 불일치 | B27: =COUNTIF(시나리오!$L$2:$L$47,A27)
A28: 확인 필요 | B28: =COUNTIF(시나리오!$L$2:$L$47,A28)
A29: 범위 밖* | B29: =COUNTIF(시나리오!$L$2:$L$47,A29)
A31: 자동화
A32: 구분 | B32: 시나리오 수
A33: 자동화 대상 Y | B33: =COUNTIF(시나리오!$N$2:$N$47,"Y")
A34: 자동화 대상 N | B34: =COUNTIF(시나리오!$N$2:$N$47,"N")
A35: Playwright 구현됨 | B35: =COUNTA(시나리오!$O$2:$O$47)
A37: 실행 결과
A38: 구분 | B38: 시나리오 수
A39: 미실행 | B39: =COUNTIF(시나리오!$R$2:$R$47,A39)
A40: 통과 | B40: =COUNTIF(시나리오!$R$2:$R$47,A40)
A41: 실패 | B41: =COUNTIF(시나리오!$R$2:$R$47,A41)
A42: 보류 | B42: =COUNTIF(시나리오!$R$2:$R$47,A42)

Sheet 삭제·병합 내역
A1: 통합본 ID | B1: 시나리오 | C1: 처리 | D1: 사유 | E1: 합쳐진 대상(최종 ID)
A2: E2E-005 | B2: 로그인 상태에서 /login 에 가면 목록으로 간다 | C2: 삭제 | D2: 로그인 상태에서 /login 접속 시 이동 확인은 가치가 낮음(핵심 로직이 아님)
A3: E2E-007 | B3: 주문 추가 화면의 시작 상태 | C3: 삭제 | D3: 기본값 표시 확인뿐이라 가치가 낮음
A4: E2E-019 | B4: 모든 안이 주문한 수량을 정확히 가져온다 | C4: 삭제 | D4: 단위 테스트 PlannerTest.everyOptionCollectsExactlyWhatWasOrdered가 이미 검증하므로 E2E에서는 중복
A5: E2E-020 | B5: 방문 횟수와 1회 적재량이 재고 상한을 지킨다 | C5: 삭제 | D5: 단위 테스트 PlannerTest.visitsAreCeilOfOrderOverStockLimit·overStockLimitOrderIsCollectedInSeveralRoundTrips가 이미 검증하므로 E2E에서는 중복
A6: E2E-021 | B6: 한 나라는 한 척의 배만 방문한다 | C6: 삭제 | D6: 단위 테스트 PlannerTest.eachCountryIsVisitedByOneShipOnly가 이미 검증하므로 E2E에서는 중복
A7: E2E-022 | B7: 사용하는 배는 선박 수와 주문 있는 나라 수 중 작은 값 이하다 | C7: 삭제 | D7: 단위 테스트 PlannerTest.usesAtMostAvailableShips가 이미 검증하므로 E2E에서는 중복
A8: E2E-023 | B8: 총 비용 = 생산 원가 + 운항비, 소요 일수 = 마지막 귀환일 | C8: 삭제 | D8: 단위 테스트 PlannerTest.productionCostIsCellsTimesUnitCost 등가 이미 검증하므로 E2E에서는 중복
A9: E2E-024 | B9: 같은 입력은 매번 같은 결과가 나온다 | C9: 삭제 | D9: 경로 계산 규칙(같은 입력은 같은 결과)은 단위 테스트 영역이라 E2E에서는 중복
A10: E2E-025 | B10: 배 한 척으로 줄이면 모든 안이 한 척만 쓴다 | C10: 삭제 | D10: 단위 테스트 PlannerTest.usesAtMostAvailableShips가 이미 검증하므로 E2E에서는 중복 (마스터 반영은 마스터 시나리오가 확인)
A11: E2E-026 | B11: 지도 애니메이션을 조작할 수 있다 | C11: 삭제 | D11: PRD에 없는 화면 기능이라 핵심 로직이 아님
A12: E2E-027 | B12: 경로안 카드에는 선택 버튼만 있고 직접 고치는 입력칸이 없다 | C12: 삭제 | D12: 범위 밖 기능이 없음을 확인하는 것이라 가치가 낮음
A13: E2E-029 | B13: 일별 나라별 재고가 재고 상한을 넘지 않는다 | C13: 삭제 | D13: 단위 테스트 PlannerTest.productionStopsAtStockLimitUntilPickup가 이미 검증하므로 E2E에서는 중복
... A22: E2E-071 | B22: 메모에 특수 문자를 넣어도 화면이 깨지지 않는다 | C22: 삭제 | D22: 보안 요건은 범위 밖으로 확정되어 존재 목적이 약함
A23: E2E-008 | B23: 총 수량을 바꾸면 4개국에 균등 분배된다 | C23: 병합 | D23: 수량 게이지 조정 동작으로 같은 시나리오 | E23: E2E-006
A24: E2E-010 | B24: 이웃과 합친 값을 넘길 수 없다 | C24: 병합 | D24: 수량 게이지 조정 동작으로 같은 시나리오 | E24: E2E-006
A25: E2E-014 | B25: 합계 하한(1K)·상한(100,000K) 경계값은 계산된다 | C25: 병합 | D25: 수량 하한·상한 검증으로 같은 시나리오 | E25: E2E-008
A26: E2E-032 | B26: 메모를 적고 확정한다 | C26: 병합 | D26: 메모 유무만 다른 같은 확정 시나리오 | E26: E2E-015
A27: E2E-034 | B27: 선택하지 않은 안으로 바뀌지 않는다 | C27: 병합 | D27: 선택한 안으로 확정되는지 확인하는 같은 시나리오 | E27: E2E-016
A28: E2E-057 | B28: 진행 주문도 취소할 수 있다 | C28: 병합 | D28: 상태만 다른 같은 취소 시나리오 | E28: E2E-032
A29: E2E-060 | B29: 취소한 주문은 삭제되므로 '취소' 건수와 필터에 쌓이지 않는다 | C29: 병합 | D29: 취소 후 목록 건수 확인이 같은 시나리오 | E29: E2E-032
A30: E2E-061 | B30: 같은 시점에 들어온 두 요청은 한쪽만 성공한다 | C30: 병합 | D30: 같은 동시 변경 시나리오를 API로 한 번 더 확인한 것 | E30: E2E-034
A31: E2E-066 | B31: 운항비가 0 이하이거나 원 단위로 떨어지지 않으면 거부된다 | C31: 병합 | D31: 운항비 잘못된 값 저장 거부로 같은 시나리오 | E31: E2E-039
A32: E2E-072 | B32: 기준 정보 변경 후 신규 주문과 과거 주문이 각자의 값을 보존한다 | C32: 병합 | D32: 마스터 변경 후 과거 주문 불변 확인이 같은 시나리오 | E32: E2E-022

Sheet 출처 매핑
A1: 원본 파일 | B1: 원본 ID | C1: 원본 제목·동작 | D1: 최종 ID | E1: 처리
A2: E2E_테스트_시나리오.xlsx | B2: E2E-001 | C2: 로그인 성공 | D2: E2E-001 | E2: 유지
A3: E2E_테스트_시나리오.xlsx | B3: E2E-002 | C3: 잘못된 계정 정보로 로그인 실패 | D3: E2E-002 | E3: 유지
A4: E2E_테스트_시나리오.xlsx | B4: E2E-003 | C4: 비로그인 상태에서 화면 접근 차단 | D4: E2E-003 | E4: 유지
A5: E2E_테스트_시나리오.xlsx | B5: E2E-004 | C5: 비로그인 상태에서 API 호출 시 401 | D5: E2E-004 | E5: 유지
A6: E2E_테스트_시나리오.xlsx | B6: E2E-010 | C6: 정상 수량 입력 → 3가지 경로안 계산 | D6: E2E-011 | E6: 유지
A7: E2E_테스트_시나리오.xlsx | B7: E2E-011 | C7: 경로안 전환 비교 | D7: E2E-012 | E7: 유지
A8: E2E_테스트_시나리오.xlsx | B8: E2E-012 | C8: 경로안 간 비용·일수 대소 관계 | D8: E2E-013 | E8: 유지
A9: E2E_테스트_시나리오.xlsx | B9: E2E-013 | C9: 총 비용 = 생산 원가 + 운항비 검산 | D9: - | E9: 삭제
A10: E2E_테스트_시나리오.xlsx | B10: E2E-014 | C10: 주문 수량 전량 수거·재고 상한 준수 | D10: - | E10: 삭제
A11: E2E_테스트_시나리오.xlsx | B11: E2E-015 | C11: 재고 상한 초과 주문 → 나눠 수거 | D11: - | E11: 삭제
A12: E2E_테스트_시나리오.xlsx | B12: E2E-016 | C12: 같은 입력 재시뮬레이션 시 동일 결과 | D12: - | E12: 삭제
... A222: e2e-test-scenarios03.xlsx | B222: HJ-S15-01 | C222: 같은 확정 요청을 연달아 두 번 보낸다 | D222: - | E222: 삭제
